<?xml version="1.0" ?>
<robot name="pharma2" xmlns:xacro="http://www.ros.org/wiki/xacro">

<xacro:include filename="$(find pharma2_description)/urdf/materials.xacro" />
<xacro:include filename="$(find pharma2_description)/urdf/pharma2.trans" />
<xacro:include filename="$(find pharma2_description)/urdf/pharma2.gazebo" />
<link name="base_link">
  <inertial>
    <origin xyz="1.754420455030862e-10 0.006871969569382918 0.07408233461912865" rpy="0 0 0"/>
    <mass value="23.773820497400024"/>
    <inertia ixx="0.100968" iyy="0.064395" izz="0.125597" ixy="-0.0" iyz="-0.001996" ixz="0.0"/>
  </inertial>
  <visual>
    <origin xyz="0 0 0" rpy="0 0 0"/>
    <geometry>
      <mesh filename="package://pharma2_description/meshes/base_link.stl" scale="0.001 0.001 0.001"/>
    </geometry>
    <material name="white"/>
  </visual>
  <collision>
    <origin xyz="0 0 0" rpy="0 0 0"/>
    <geometry>
      <mesh filename="package://pharma2_description/meshes/base_link.stl" scale="0.001 0.001 0.001"/>
    </geometry>
  </collision>
</link>

<link name="left_front_1">
  <inertial>
    <origin xyz="0.006000000000000005 1.0358413515820786e-07 2.2863054563448948e-07" rpy="0 0 0"/>
    <mass value="0.10838148045272696"/>
    <inertia ixx="2e-05" iyy="1.1e-05" izz="1.1e-05" ixy="-0.0" iyz="-0.0" ixz="0.0"/>
  </inertial>
  <visual>
    <origin xyz="-0.09 -0.07571 -0.028299" rpy="0 0 0"/>
    <geometry>
      <mesh filename="package://pharma2_description/meshes/left_front_1.stl" scale="0.001 0.001 0.001"/>
    </geometry>
    <material name="black"/>
  </visual>
  <collision>
    <origin xyz="-0.09 -0.07571 -0.028299" rpy="0 0 0"/>
    <geometry>
      <mesh filename="package://pharma2_description/meshes/left_front_1.stl" scale="0.001 0.001 0.001"/>
    </geometry>
  </collision>
</link>

<link name="right_front_1">
  <inertial>
    <origin xyz="-0.006000000000000005 1.0358413517208565e-07 2.2863054563448948e-07" rpy="0 0 0"/>
    <mass value="0.10838148045272698"/>
    <inertia ixx="2e-05" iyy="1.1e-05" izz="1.1e-05" ixy="-0.0" iyz="-0.0" ixz="-0.0"/>
  </inertial>
  <visual>
    <origin xyz="0.09 -0.07571 -0.028299" rpy="0 0 0"/>
    <geometry>
      <mesh filename="package://pharma2_description/meshes/right_front_1.stl" scale="0.001 0.001 0.001"/>
    </geometry>
    <material name="black"/>
  </visual>
  <collision>
    <origin xyz="0.09 -0.07571 -0.028299" rpy="0 0 0"/>
    <geometry>
      <mesh filename="package://pharma2_description/meshes/right_front_1.stl" scale="0.001 0.001 0.001"/>
    </geometry>
  </collision>
</link>

<link name="left_back_1">
  <inertial>
    <origin xyz="0.006000000000000005 1.0358413514433007e-07 2.286305456657145e-07" rpy="0 0 0"/>
    <mass value="0.10838148045272723"/>
    <inertia ixx="2e-05" iyy="1.1e-05" izz="1.1e-05" ixy="-0.0" iyz="-0.0" ixz="0.0"/>
  </inertial>
  <visual>
    <origin xyz="-0.09 0.06429 -0.028299" rpy="0 0 0"/>
    <geometry>
      <mesh filename="package://pharma2_description/meshes/left_back_1.stl" scale="0.001 0.001 0.001"/>
    </geometry>
    <material name="black"/>
  </visual>
  <collision>
    <origin xyz="-0.09 0.06429 -0.028299" rpy="0 0 0"/>
    <geometry>
      <mesh filename="package://pharma2_description/meshes/left_back_1.stl" scale="0.001 0.001 0.001"/>
    </geometry>
  </collision>
</link>

<link name="right_back_1">
  <inertial>
    <origin xyz="-0.006000000000000005 1.0358413515820786e-07 2.2863054566224505e-07" rpy="0 0 0"/>
    <mass value="0.10838148045272696"/>
    <inertia ixx="2e-05" iyy="1.1e-05" izz="1.1e-05" ixy="0.0" iyz="-0.0" ixz="0.0"/>
  </inertial>
  <visual>
    <origin xyz="0.09 0.06429 -0.028299" rpy="0 0 0"/>
    <geometry>
      <mesh filename="package://pharma2_description/meshes/right_back_1.stl" scale="0.001 0.001 0.001"/>
    </geometry>
    <material name="black"/>
  </visual>
  <collision>
    <origin xyz="0.09 0.06429 -0.028299" rpy="0 0 0"/>
    <geometry>
      <mesh filename="package://pharma2_description/meshes/right_back_1.stl" scale="0.001 0.001 0.001"/>
    </geometry>
  </collision>
</link>

<link name="lidar_1_1">
  <inertial>
    <origin xyz="-3.618764437576268e-18 1.0358413515820786e-07 0.010000228630545671" rpy="0 0 0"/>
    <mass value="0.3082687791334984"/>
    <inertia ixx="5.8e-05" iyy="5.8e-05" izz="9.6e-05" ixy="-0.0" iyz="-0.0" ixz="-0.0"/>
  </inertial>
  <visual>
    <origin xyz="-0.0 -0.08071 -0.128299" rpy="0 0 0"/>
    <geometry>
      <mesh filename="package://pharma2_description/meshes/lidar_1_1.stl" scale="0.001 0.001 0.001"/>
    </geometry>
    <material name="blue"/>
  </visual>
  <collision>
    <origin xyz="-0.0 -0.08071 -0.128299" rpy="0 0 0"/>
    <geometry>
      <mesh filename="package://pharma2_description/meshes/lidar_1_1.stl" scale="0.001 0.001 0.001"/>
    </geometry>
  </collision>
</link>

<joint name="Rev1" type="continuous">
  <origin xyz="0.09 0.07571 0.028299" rpy="0 0 0"/>
  <parent link="base_link"/>
  <child link="left_front_1"/>
  <axis xyz="1.0 -0.0 0.0"/>
</joint>

<joint name="Rev2" type="continuous">
  <origin xyz="-0.09 0.07571 0.028299" rpy="0 0 0"/>
  <parent link="base_link"/>
  <child link="right_front_1"/>
  <axis xyz="-1.0 -0.0 0.0"/>
</joint>

<joint name="Rev3" type="continuous">
  <origin xyz="0.09 -0.06429 0.028299" rpy="0 0 0"/>
  <parent link="base_link"/>
  <child link="left_back_1"/>
  <axis xyz="1.0 -0.0 0.0"/>
</joint>

<joint name="Rev4" type="continuous">
  <origin xyz="-0.09 -0.06429 0.028299" rpy="0 0 0"/>
  <parent link="base_link"/>
  <child link="right_back_1"/>
  <axis xyz="-1.0 -0.0 0.0"/>
</joint>

<joint name="Rigid5" type="fixed">
  <origin xyz="0.0 0.08071 0.128299" rpy="0 0 0"/>
  <parent link="base_link"/>
  <child link="lidar_1_1"/>
</joint>

</robot>
